<?xml version="1.0"?>
<robot name="my_autonomous_car" xmlns:xacro="http://www.ros.org/wiki/xacro">
    
  <!-- Robot Configuration -->
  <link name="base_footprint"/>

  <joint name="base_joint" type="fixed">
    <parent link="base_footprint"/>
    <child link="base_link"/>
    <origin xyz="0 0 0.1" rpy="0 0 0"/>
  </joint>

  <!-- Colors -->
  <material name="black">
    <color rgba="0.0 0.0 0.0 1.0"/>
  </material>
  <material name="blue">
    <color rgba="0.0 0.0 0.8 1.0"/>
  </material>

  <!-- Base Link -->
  <link name="base_link">
    <visual>
      <geometry>
        <box size="0.5 0.3 0.1"/>
      </geometry>
      <material name="blue"/>
    </visual>
    <collision>
      <geometry>
        <box size="0.5 0.3 0.1"/>
      </geometry>
    </collision>
    <inertial>
      <mass value="5.0"/>
      <inertia ixx="0.1" ixy="0" ixz="0" iyy="0.1" iyz="0" izz="0.1"/>
    </inertial>
  </link>

  <!-- Front Left Wheel -->
  <link name="front_left_wheel">
    <visual>
      <geometry>
        <cylinder radius="0.05" length="0.04"/>
      </geometry>
      <material name="black"/>
    </visual>
    <collision>
      <geometry>
        <cylinder radius="0.05" length="0.04"/>
      </geometry>
    </collision>
    <inertial>
      <mass value="0.5"/>
      <inertia ixx="0.001" ixy="0" ixz="0" iyy="0.001" iyz="0" izz="0.001"/>
    </inertial>
  </link>

 <joint name="front_left_wheel_joint" type="continuous">
    <parent link="base_link"/>
    <child link="front_left_wheel"/>
    <origin xyz="0.15 0.17 -0.05" rpy="-1.5708 0 0"/>
    <axis xyz="0 0 1"/>
    <dynamics damping="0.0" friction="0.0"/>
</joint>

  <!-- Front Right Wheel -->
  <link name="front_right_wheel">
    <visual>
      <geometry>
        <cylinder radius="0.05" length="0.04"/>
      </geometry>
      <material name="black"/>
    </visual>
    <collision>
      <geometry>
        <cylinder radius="0.05" length="0.04"/>
      </geometry>
    </collision>
    <inertial>
      <mass value="0.5"/>
      <inertia ixx="0.001" ixy="0" ixz="0" iyy="0.001" iyz="0" izz="0.001"/>
    </inertial>
  </link>

<joint name="front_right_wheel_joint" type="continuous">
    <parent link="base_link"/>
    <child link="front_right_wheel"/>
    <origin xyz="0.15 -0.17 -0.05" rpy="-1.5708 0 0"/>
    <axis xyz="0 0 1"/>
    <dynamics damping="0.0" friction="0.0"/>
</joint>

  <!-- Rear Left Wheel -->
  <link name="rear_left_wheel">
    <visual>
      <geometry>
        <cylinder radius="0.05" length="0.04"/>
      </geometry>
      <material name="black"/>
    </visual>
    <collision>
      <geometry>
        <cylinder radius="0.05" length="0.04"/>
      </geometry>
    </collision>
    <inertial>
      <mass value="0.5"/>
      <inertia ixx="0.001" ixy="0" ixz="0" iyy="0.001" iyz="0" izz="0.001"/>
    </inertial>
  </link>

 <joint name="rear_left_wheel_joint" type="continuous">
    <parent link="base_link"/>
    <child link="rear_left_wheel"/>
    <origin xyz="-0.15 0.17 -0.05" rpy="-1.5708 0 0"/>
    <axis xyz="0 0 1"/>
    <dynamics damping="0.0" friction="0.0"/>
</joint>

  <!-- Rear Right Wheel -->
  <link name="rear_right_wheel">
    <visual>
      <geometry>
        <cylinder radius="0.05" length="0.04"/>
      </geometry>
      <material name="black"/>
    </visual>
    <collision>
      <geometry>
        <cylinder radius="0.05" length="0.04"/>
      </geometry>
    </collision>
    <inertial>
      <mass value="0.5"/>
      <inertia ixx="0.001" ixy="0" ixz="0" iyy="0.001" iyz="0" izz="0.001"/>
    </inertial>
  </link>

<joint name="rear_right_wheel_joint" type="continuous">
    <parent link="base_link"/>
    <child link="rear_right_wheel"/>
    <origin xyz="-0.15 -0.17 -0.05" rpy="-1.5708 0 0"/>
    <axis xyz="0 0 1"/>
    <dynamics damping="0.0" friction="0.0"/>
</joint>

  <!-- LiDAR Link -->
  <link name="lidar_link">
    <visual>
      <geometry>
        <cylinder radius="0.05" length="0.05"/>
      </geometry>
      <material name="black"/>
    </visual>
    <collision>
      <geometry>
        <cylinder radius="0.05" length="0.05"/>
      </geometry>
    </collision>
    <inertial>
      <mass value="0.1"/>
      <inertia ixx="0.001" ixy="0" ixz="0" iyy="0.001" iyz="0" izz="0.001"/>
    </inertial>
  </link>

  <joint name="lidar_joint" type="fixed">
    <parent link="base_link"/>
    <child link="lidar_link"/>
    <origin xyz="0 0 0.1" rpy="0 0 0"/>
  </joint>

  <!-- ROS2 Control Configuration -->
  <ros2_control name="car_control" type="system">
    <hardware>
      <plugin>gazebo_ros2_control/GazeboSystem</plugin>
    </hardware>
    
    <!-- Front Left Wheel -->
    <joint name="front_left_wheel_joint">
      <command_interface name="velocity">
        <param name="min">-10</param>
        <param name="max">10</param>
      </command_interface>
      <state_interface name="position"/>
      <state_interface name="velocity"/>
    </joint>

    <!-- Front Right Wheel -->
    <joint name="front_right_wheel_joint">
      <command_interface name="velocity">
        <param name="min">-10</param>
        <param name="max">10</param>
      </command_interface>
      <state_interface name="position"/>
      <state_interface name="velocity"/>
    </joint>

    <!-- Rear Left Wheel -->
    <joint name="rear_left_wheel_joint">
      <command_interface name="velocity">
        <param name="min">-10</param>
        <param name="max">10</param>
      </command_interface>
      <state_interface name="position"/>
      <state_interface name="velocity"/>
    </joint>

    <!-- Rear Right Wheel -->
    <joint name="rear_right_wheel_joint">
      <command_interface name="velocity">
        <param name="min">-10</param>
        <param name="max">10</param>
      </command_interface>
      <state_interface name="position"/>
      <state_interface name="velocity"/>
    </joint>
  </ros2_control>

  <!-- Gazebo ROS2 Control Plugin -->
 <gazebo>
    <plugin name="gazebo_ros2_control" filename="libgazebo_ros2_control.so">
      <parameters>$(find my_slam_pkg)/config/controllers.yaml</parameters>
      <robot_sim_type>gazebo_ros2_control/GazeboSystem</robot_sim_type>
    </plugin>
  </gazebo>

  <!-- LiDAR Sensor Configuration -->
  <gazebo reference="lidar_link">
    <sensor type="ray" name="lidar">
      <pose>0 0 0 0 0 0</pose>
      <visualize>true</visualize>
      <update_rate>10</update_rate>
      <ray>
        <scan>
          <horizontal>
            <samples>360</samples>
            <resolution>1</resolution>
            <min_angle>-3.14159</min_angle>
            <max_angle>3.14159</max_angle>
          </horizontal>
        </scan>
        <range>
          <min>0.3</min>
          <max>10.0</max>
          <resolution>0.01</resolution>
        </range>
      </ray>
      <plugin name="laser_controller" filename="libgazebo_ros_ray_sensor.so">
        <ros>
          <remapping>~/out:=scan</remapping>
        </ros>
        <output_type>sensor_msgs/LaserScan</output_type>
        <frame_name>lidar_link</frame_name>
      </plugin>
    </sensor>
  </gazebo>

  <!-- Material Properties -->
  <gazebo reference="base_link">
    <material>Gazebo/Blue</material>
  </gazebo>

<gazebo reference="front_left_wheel">
    <material>Gazebo/Black</material>
    <mu1>0.8</mu1>
    <mu2>0.8</mu2>
    <kp>100000000.0</kp>
    <kd>1.0</kd>
    <fdir1>1 0 0</fdir1>
</gazebo>

<gazebo reference="front_right_wheel">
    <material>Gazebo/Black</material>
    <mu1>0.8</mu1>
    <mu2>0.8</mu2>
    <kp>100000000.0</kp>
    <kd>1.0</kd>
    <fdir1>1 0 0</fdir1>
</gazebo>

<gazebo reference="rear_left_wheel">
    <material>Gazebo/Black</material>
    <mu1>0.8</mu1>
    <mu2>0.8</mu2>
    <kp>100000000.0</kp>
    <kd>1.0</kd>
    <fdir1>1 0 0</fdir1>
</gazebo>

<gazebo reference="rear_right_wheel">
    <material>Gazebo/Black</material>
    <mu1>0.8</mu1>
    <mu2>0.8</mu2>
    <kp>100000000.0</kp>
    <kd>1.0</kd>
    <fdir1>1 0 0</fdir1>
</gazebo>

  <gazebo reference="lidar_link">
    <material>Gazebo/Black</material>
  </gazebo>

</robot>