<?xml version="1.0"?>
<!-- 
File: src/my_slam_pkg/urdf/esp32_real_robot.urdf.xacro
Real robot URDF for ESP32 + RPLidar A1 hardware
-->
<robot name="esp32_real_robot" xmlns:xacro="http://www.ros.org/wiki/xacro">

  <!-- Arguments -->
  <xacro:arg name="use_sim_time" default="false"/>
    
  <!-- Robot Configuration -->
  <link name="base_footprint"/>

  <joint name="base_joint" type="fixed">
    <parent link="base_footprint"/>
    <child link="base_link"/>
    <origin xyz="0 0 0.1" rpy="0 0 0"/>
  </joint>

  <!-- Colors -->
  <material name="black">
    <color rgba="0.0 0.0 0.0 1.0"/>
  </material>
  <material name="blue">
    <color rgba="0.0 0.0 0.8 1.0"/>
  </material>
  <material name="red">
    <color rgba="0.8 0.0 0.0 1.0"/>
  </material>

  <!-- Base Link - Robot chassis -->
  <link name="base_link">
    <visual>
      <geometry>
        <box size="0.5 0.3 0.1"/>
      </geometry>
      <material name="blue"/>
    </visual>
    <collision>
      <geometry>
        <box size="0.5 0.3 0.1"/>
      </geometry>
    </collision>
    <inertial>
      <mass value="5.0"/>
      <origin xyz="0 0 0" rpy="0 0 0"/>
      <inertia ixx="0.1" ixy="0" ixz="0" iyy="0.1" iyz="0" izz="0.1"/>
    </inertial>
  </link>

  <!-- Wheel macro for real robot -->
  <xacro:macro name="wheel" params="prefix x_pos y_pos">
    <link name="${prefix}_wheel">
      <visual>
        <geometry>
          <cylinder radius="0.05" length="0.04"/>
        </geometry>
        <material name="black"/>
      </visual>
      <collision>
        <geometry>
          <cylinder radius="0.05" length="0.04"/>
        </geometry>
      </collision>
      <inertial>
        <mass value="0.5"/>
        <origin xyz="0 0 0" rpy="0 0 0"/>
        <inertia ixx="0.001" ixy="0" ixz="0" iyy="0.001" iyz="0" izz="0.001"/>
      </inertial>
    </link>

    <joint name="${prefix}_wheel_joint" type="continuous">
      <parent link="base_link"/>
      <child link="${prefix}_wheel"/>
      <origin xyz="${x_pos} ${y_pos} -0.05" rpy="-1.5708 0 0"/>
      <axis xyz="0 0 1"/>
      <dynamics damping="0.05" friction="0.05"/>
    </joint>
  </xacro:macro>

  <!-- Create all four wheels -->
  <xacro:wheel prefix="front_left" x_pos="0.15" y_pos="0.17"/>
  <xacro:wheel prefix="front_right" x_pos="0.15" y_pos="-0.17"/>
  <xacro:wheel prefix="rear_left" x_pos="-0.15" y_pos="0.17"/>
  <xacro:wheel prefix="rear_right" x_pos="-0.15" y_pos="-0.17"/>

  <!-- RPLidar A1 Link -->
  <link name="lidar_link">
    <visual>
      <geometry>
        <cylinder radius="0.04" length="0.06"/>
      </geometry>
      <material name="red"/>
    </visual>
    <collision>
      <geometry>
        <cylinder radius="0.04" length="0.06"/>
      </geometry>
    </collision>
    <inertial>
      <mass value="0.2"/>
      <origin xyz="0 0 0" rpy="0 0 0"/>
      <inertia ixx="0.001" ixy="0" ixz="0" iyy="0.001" iyz="0" izz="0.001"/>
    </inertial>
  </link>

  <!-- RPLidar mounting joint -->
  <joint name="lidar_joint" type="fixed">
    <parent link="base_link"/>
    <child link="lidar_link"/>
    <origin xyz="0 0 0.15" rpy="0 0 0"/>
  </joint>

  <!-- ESP32 Electronics Box (visual representation) -->
  <link name="esp32_link">
    <visual>
      <geometry>
        <box size="0.1 0.1 0.03"/>
      </geometry>
      <material name="black"/>
    </visual>
    <collision>
      <geometry>
        <box size="0.1 0.1 0.03"/>
      </geometry>
    </collision>
    <inertial>
      <mass value="0.1"/>
      <origin xyz="0 0 0" rpy="0 0 0"/>
      <inertia ixx="0.001" ixy="0" ixz="0" iyy="0.001" iyz="0" izz="0.001"/>
    </inertial>
  </link>

  <joint name="esp32_joint" type="fixed">
    <parent link="base_link"/>
    <child link="esp32_link"/>
    <origin xyz="-0.15 0 0.07" rpy="0 0 0"/>
  </joint>

  <!-- ROS2 Control Configuration for ESP32 Hardware -->
  <ros2_control name="esp32_motor_controller" type="system">
    <hardware>
      <plugin>my_slam_pkg/ESP32HardwareInterface</plugin>
      <param name="wheel_radius">0.05</param>
      <param name="wheel_separation">0.34</param>
      <param name="cmd_vel_topic">/cmd_vel</param>
      <param name="joint_states_topic">/joint_states</param>
      <param name="use_sim_hardware">false</param>
    </hardware>
    
    <!-- Front Left Wheel -->
    <joint name="front_left_wheel_joint">
      <command_interface name="velocity">
        <param name="min">-10</param>
        <param name="max">10</param>
      </command_interface>
      <state_interface name="position"/>
      <state_interface name="velocity"/>
      <state_interface name="effort"/>
    </joint>

    <!-- Front Right Wheel -->
    <joint name="front_right_wheel_joint">
      <command_interface name="velocity">
        <param name="min">-10</param>
        <param name="max">10</param>
      </command_interface>
      <state_interface name="position"/>
      <state_interface name="velocity"/>
      <state_interface name="effort"/>
    </joint>

    <!-- Rear Left Wheel -->
    <joint name="rear_left_wheel_joint">
      <command_interface name="velocity">
        <param name="min">-10</param>
        <param name="max">10</param>
      </command_interface>
      <state_interface name="position"/>
      <state_interface name="velocity"/>
      <state_interface name="effort"/>
    </joint>

    <!-- Rear Right Wheel -->
    <joint name="rear_right_wheel_joint">
      <command_interface name="velocity">
        <param name="min">-10</param>
        <param name="max">10</param>
      </command_interface>
      <state_interface name="position"/>
      <state_interface name="velocity"/>
      <state_interface name="effort"/>
    </joint>
  </ros2_control>

</robot>